Workbook

Sheet Listas01
A1: EPS | C1: Fondos de Pensiones | E1: cajas de compensación | G1: ARL | I1: Nómina Cooperativa | K1: asignación salarial | M1: Asignación salarial | O1: Dotacion Ctas Ctables | Q1: Propiedad Retención | S1: Tipos de identificacion | U1: Ciudades | W1: Tipos de Direccion | Y1: Unidad de Medida | AA1: Grupo Uno | AC1: Tipo de IVA | AE1: Clasificación | AG1: Cuentas anticipos empleados | AI1: Anticipo Prestaciones: | AK1: Descontar Nómina | AM1: Concepto Prestamo | AO1: Estado Prestamo | AQ1: Cuenta liquidacion definitiva | AS1: Base salario integral | AU1: Propiedad Activa | AW1: Acumulados | AY1: Nombre de la actividad Economica | BA1: Ingresos | BC1: Inventarios | BE1: Costos | BG1: Bancos | BI1: Tipo de C. | BK1: Autorretencion especial a titulo de renta | BM1: clasificaciones | BO1: Tipos de Depreciacion | BQ1: Clasificacion Niff | BS1: Clasificacion Activo Fijo | BU1: Areas | BW1: Clase | BY1: Tipo de Cotizante | CA1: Aprendiz Sena | CC1: Subtipo cotizante | CE1: Tipo Cuenta Bancaria | CG1: Termino Contrato | CI1: Modalidad | CK1: Tarifa ARL | CM1: según aplica | CO1: MESES PROMEDIAR | CQ1: PROMEDIO | CS1: Agrupacion | CU1: Efecto | CW1: PUC | CY1: CUENTAS DE RETENCION | DA1: Tipo de contribuyente | DC1: Agrupación Actividad Económica | DE1: Perfil Usuarios | DG1: Pregunta de seguridad | DI1: Tipo de Usuario | DK1: Tipo Vinculación Laboral | DM1: Unidad de Medida FE | DO1: Clasificacion DIAN | DQ1: Digitos Nomina | DS1: Tipo Contrato | DU1: Cargos | DW1: Clasificación Dian
A2: ALIANZA MEDELLIN ANTIOQUIA EPS | C2: CAJANAL | E2: AFIDRO | G2: ARL SEGUROS DE VIDA COLPATRIA SA | I2: Alimentación S | K2: Cuota de Sostenimiento | M2: Alimentación S | O2: 510551 | Q2: Entidades Sin Animo De Lucro | S2: CC | U2: Abejorral | W2: Bodega | Y2: " | AA2: ACTIVOS FIJOS | AC2: AIU Gravado | AE2: Activo Fijo | AG2: 13050501 DEUDORES NACIONALES | AI2: Ahorro Descuento | AK2: 1era Nómina del mes | AM2: Adquisición de Vivienda | AO2: Cancelado | AQ2: 251010 Cesantías | AS2: Sobre el 100% del origen del IBC | AU2: Administrador Impuestos Distritales; | AW2: Auxilio de transporte | AY2: 10 Asalariados. | BA2: 410505 DESCUENTOS | BC2: 1405 MATERIAS PRIMAS | BE2: 6105 AGRICULTURA, GANADERIA, CAZA Y SILVICULTURA | BG2: ABN AMRO BANK | BI2: Ahorros | BK2: 0.004 | BM2: Activo Fijo | BO2: Línea Recta | BQ2: Activos Productivos | BS2: Propiedad, Planta y Equipo | BU2: Administrativa | BW2: Aprendiz SENA | BY2: Dependiente | CA2: Aprendices del SENA en etapa lectiva | CC2: Ninguno | CE2: Corriente | CG2: Fijo | CI2: Fijo | CK2: 6.96 | CM2: SI | CO2: 3 MESES | CQ2: Proyectar al equivalente mensual | CS2: Otros Deducidos | CU2: Disminuye | CW2: Comercial | CY2: 13551501 RETENCION DEBITO POR VENTAS DE PRODUCTOS0,035 | DA2: Persona Jurídica o asimilada | DC2: Comercial | DE2: Auxiliar Contable | DG2: Apellido de tu mejor amigo de la niñez | DI2: Administrador | DK2: Aprendices del SENA en etapa Lectiva | DM2: Pulgada - " | DO2: Normal | DQ2: 0 | DS2: Fijo | DU2: ='Cargos Nomina-Centros de trabaj'!B2 -> Auxiliar Contable | DW2: Normal
A3: CAFESALUD EPS | C3: CAPRECOM | E3: CAFAM | G3: ARL SURA | I3: Anticipo Devengado (P) | K3: Salario Integral | M3: Anticipo Devengado (P) | O3: 520551 | Q3: Grande Contribuyente Autorretenedor | S3: Cédula de extranjería | U3: Abrego | W3: Casa | Y3: µm | AA3: CONTABILIZACIONES AUTOMATICAS | AC3: AIU No Gravado | AE3: Consignación o Depósito | AG3: 13050502 CLIENTES REMISIONES | AI3: Anticipo Cesantías | AK3: 2da Nómina del mes | AM3: Eduación | AO3: Debe | AQ3: 251501 Intereses | AS3: Sobre Origen del IBC menos porcentaje de salario Integral | AU3: Administrador Impuestos Nacionales; | AW3: Bonificación Permanente | AY3: 101 Procesamiento y conservación de carne, pescado, crustáceos y moluscos. | BA3: 410510 CULTIVOS DE HORTALIZAS, LEGUMBRES Y PLANTAS ORNAMENTALES | BC3: 1430 PRODUCTOS TERMINADOS | BE3: 6110 PESCA | BG3: BANCO AGRARIO DE COLOMBIA | BI3: Corriente | BK3: 0.008 | BM3: Consignación o Depósito | BO3: Reducción de Saldos | BQ3: Activos No Productivos | BS3: Propiedades de Inversion | BU3: Produccion | BW3: Normal | BY3: Servicio Domestico | CA3: Aprendices del SENA en etapa productiva | CC3: Dependiente pensionado por vejez activo | CE3: Ahorros | CG3: Indefinido | CI3: Variable | CK3: 4.35 | CM3: NO | CO3: 6 MESES | CQ3: Valor Devengado | CS3: Otros Devengados | CU3: Aumenta | CW3: Cooperativo | CY3: 13551502 RETENCION DEBITO POR VENTA DE SERVICIOS0,04 | DA3: Persona Natural o asimilada | DC3: Financiera | DE3: Cartera y Cobranza | DG3: Apellido de tu musico favorito | DI3: Usuario | DK3: Aprendices del SENA en etapa productiva | DM3: Micrometro - µm | DO3: Exportador | DQ3: 2 | DS3: Indefinido | DU3: ='Cargos Nomina-Centros de trabaj'!B3 -> Mensajero | DW3: Exportador
A4: CAJANAL EPS | C4: COLFONDOS S.A. AFPC | E4: CAFAMAZ | G4: ARP ALFA | I4: Antigüedad P | K4: Sueldo | M4: Antigüedad P | O4: 730551 | Q4: Grande Contribuyente No Autorretenedor | S4: CONSUMIDOR FINAL | U4: Abriaquí | W4: Empresa/Oficina | Y4: Año | AA4: DOTACIONES | AC4: Excluido | AE4: Diferido | AG4: 13051001 CLIENTES DEL EXTERIOR | AI4: Anticipo Intereses de Cesantías | AK4: En todas | AM4: Mejora de vivienda | AQ4: 252001 Prima | AU4: Aseguradora; | AW4: Comisiones | AY4: 1011 Procesamiento y conservación de carne y productos cárnicos. | BA4: 410515 CULTIVOS DE FRUTAS, NUECES Y PLANTAS AROMATICAS | BC4: 1435 MERCANCIAS NO FABRICADAS POR LA EMPRESA | BE4: 6115 EXPLOTACION DE MINAS Y CANTERAS | BG4: BANCO AV VILLAS | BK4: 0.55 | BM4: Diferido | BO4: Suma de Dígitos | BU4: Ventas | BW4: Salario Integral | BY4: Independiente | CC4: Independiente pensionado por vejez activo | CK4: 2.436 | CO4: 12 MESES | CU4: Sin Efecto | CW4: Salud - Res 1121 | CY4: 13551503 RETENCION EN LA FUENTE POR VENTA DE SERVICIOS PROFESIONALES0,11 | DA4: Gran Contribuyente | DC4: Industrial | DE4: Compras y manejo de proveedores | DG4: Autor Favorito | DK4: Contrato Laboral | DM4: Año - Año | DO4: Importador | DS4: Labor Contratada | DU4: ='Cargos Nomina-Centros de trabaj'!B4 -> Servicios Generales | DW4: Importador
A5: CALISALUD EPS | C5: COLPENSIONES | E5: CAFASUR | G5: BBVA SEGUROS DE VIDA COLOMBIA S.A. | I5: Aportes cuentas AFC | M5: Auxilio de Transporte | Q5: Instituciones del Estado Publicos y Otros | S5: Documento de identificación extranjero | U5: Acacías | W5: Sucursal | Y5: cm | AA5: INVENTARIOS DE PRODUCTOS EN PROCESO | AC5: Exento | AE5: Dotación | AG5: 130515 DEUDORES DEL SISTEMA | AI5: Anticipo Nómina | AM5: Préstamo por calamidad doméstica | AQ5: 252501 Vacaciones | AU5: Banco; | AW5: Festivo Doble | AY5: 1012 Procesamiento y conservación de pescados, crustáceos y moluscos. | BA5: 410520 CULTIVO DE CAFE | BC5: 1440 BIENES RAICES PARA LA VENTA | BE5: 6120 INDUSTRIAS MANUFACTURERAS | BG5: BANCO BBVA | BK5: 1.1 | BM5: Dotación | BO5: Unidades Producidas | BW5: Salario Inferior al Minimo | BY5: Madre comunitaria | CC5: Cotizante no obligado a cotizacion a pensiones por edad | CK5: 1.044 | CW5: Salud - Cir. Ext. 016 | CY5: 13551504 RETENCION EN LA FUENTE POR VENTA DE SERVICIOS DE VIGILANCIA0,02 | DA5: Regimen Simple | DC5: Servicios | DE5: Contador | DG5: Calle donde creciste | DK5: Estudiante - Pasantía | DM5: Centimetro - cm | DO5: Sociedad de comercialización Internacional | DS5: Definido menos de un año | DU5: ='Cargos Nomina-Centros de trabaj'!B5 -> Gerente | DW5: Sociedad de comercialización Internacional
A6: CAPRECOM | C6: OLD MUTUAL PENSIONES Y CESANTÍAS S.A. | E6: CAJA COLOMBIANA DE SUBSIDIO FAMILIAR COLSUBSIDIO | G6: COLMENA RIESGOS PROFESIONALES | I6: Aportes voluntarios pensión | M6: Auxilio de Vestido | Q6: Persona Juridica | S6: Documento de Identificación extranjero Persona Jurídica | U6: Acandí | Y6: cm² | AA6: INVENTARIOS DE PRODUCTOS TERMINADOS | AC6: Gravado | AE6: Gasto | AG6: 131005 CASA MATRIZ | AI6: Anticipo Prima | AU6: Cliente; | AW6: Festivo Sencillo | AY6: 102 Procesamiento y conservación de frutas, legumbres, hortalizas y turbérculo | BA6: 410525 CULTIVO DE FLORES | BC6: 1445 SEMOVIENTES | BE6: 6125 SUMINISTRO DE ELECTRICIDAD, GAS Y AGUA | BG6: BANCO CAJA SOCIAL BCSC | BK6: 1.9 | BM6: Gasto | BY6: Aprendices del SENA en etapa lectiva | CC6: Cotizante con requisitos cumplidos para pension | CK6: 0.522 | CW6: Servicios Públicos | CY6: 13551505 RETENCION EN LA FUENTE POR VENTA DE SERVICIOS DE TRANSPORTE0,01 | DE6: Facturacion y Ventas | DG6: Comida favorita cuando eras niño | DK6: Estudiantes (Régimen especial Ley 789/2002) | DM6: Centimetro² - cm² | DO6: Tercero en Zona Franca | DS6: Contrato de aprendizaje | DU6: ='Cargos Nomina-Centros de trabaj'!B6 -> Vendedor | DW6: Tercero en Zona Franca
A7: CAPRESOCA EPS | C7: PENSIONES DE ANTIOQUIA | E7: CAJA DE COMPENSACION FAMILIAR CAJACOPI | G7: COMPAÑÍA DE SEGUROS BOLIVAR SA | I7: Ausencias | M7: Auxilio Vehiculo (No Salarial) | Q7: Persona Jurídica Autorretenedor | S7: NIT | U7: Acevedo | Y7: cm³ | AA7: INVENTARIOS MATERIAS PRIMAS | AC7: No Gravados | AE7: Intangibles | AG7: 131010 COMPAÑIAS VINCULADAS | AI7: Anticipo Vacaciones | AU7: Empleado; | AW7: Hora Extra Festiva | AY7: 1020 Procesamiento y conservación de frutas, legumbres, hortalizas y tubérculos. | BA7: 410530 CULTIVO DE CAÑA DE AZUCAR | BC7: 1450 TERRENOS | BE7: 6130 CONSTRUCCION | BG7: BANCO COLPATRIA | BK7: 2.2 | BM7: Intangibles | BY7: Funcionarios Públicos sin tope maximo en el IBC | CC7: Cotizante con indemnizacion sustituta o devolucion de saldos | CW7: Sector Público | CY7: 13551506 RETENCION EN LA FUENTE SERVICIO DE OBRA0,01 | DE7: Gerente | DG7: Hospital donde naciste | DK7: Estudiantes de posgrado en Salud | DM7: Centimetro³ - cm³ | DO7: Zonas Exentas y/o Tercero Exentos | DU7: ='Cargos Nomina-Centros de trabaj'!B7 -> 0 | DW7: Zonas Exentas y/o Tercero Exentos
A8: COLMEDICA EPS | C8: PORVENIR S.A. AFPC | E8: CAJA DE COMPENSACION FAMILIAR COMFANORTE | G8: LA EQUIDAD SEGUROS DE VIDA | I8: Auxilio de movilización | M8: Auxilio Vivienda P (Salarial) | Q8: Persona Natural Autorretenedor | S8: NUIP | U8: Achí | Y8: D | AA8: MANO DE OBRA | AE8: Otros Conceptos | AG8: 131015 ACCIONISTAS O SOCIOS | AI8: Fondo empleados Descuento | AU8: Fondo; | AW8: Hora Extra Festiva Nocturna | AY8: 103 Elaboración de aceites y grasas de origen vegetal y animal. | BA8: 410545 OTROS CULTIVOS AGRICOLAS | BE8: 6135 COMERCIO AL POR MAYOR Y AL POR MENOR | BG8: BANCO DAVIVIENDA | BK8: 3.6 | BM8: Otros Conceptos | BY8: Aprendices del SENA en etapa productiva | CC8: Cotizante perteneciente a regimen exceptuado de pensiones o a entidades para recibir aportes exclusivamente de un grupo de sus propios trabajadores | CY8: 13551507 RETENCION EN LA FUENTE SERVICIO DE ALQUILER BIENES MUEBLES 4%0,04 | DE8: Inventarios y Almacen | DG8: Libro Favorito | DK8: Pensionado | DM8: D - Día | DO8: Importador zona franca | DU8: ='Cargos Nomina-Centros de trabaj'!B8 -> 0 | DW8: Importador zona franca
A9: COMFACHOCO EPS S | C9: PROTECCIÓN S.A. AFPC | E9: CAJA DE COMPENSACION FAMILIAR DE ANTIOQUIA | G9: LA PREVISORA SA COMPAÑÍA DE SEGUROS | I9: Auxilio de Vestido | M9: Bonificación Mera Liberalidad P (No Salarial) | O9: =TRIM(O5) | Q9: Persona Natural No Responsable del IVA | S9: OTRO | U9: Agrado | Y9: Docena | AA9: PRODUCTOS NO FABRICADOS POR LA EMPRESA | AE9: Producto | AG9: 131020 PARTICULARES | AI9: Libranza Descuento | AU9: Proveedor; | AW9: Hora Extra Festiva Diurna | AY9: 1030 Elaboración de aceites y grasas de origen vegetal y animal. | BA9: 410550 CRIA DE OVEJAS, CABRAS, ASNOS, MULAS Y BURDEGANOS | BE9: 6140 HOTELES Y RESTAURANTES | BG9: BANCO DE BOGOTÁ | BK9: 4,50 | BM9: Producto | BY9: Estudiantes de postgrado en salud (Decreto 190 de 1996) | CC9: Cotizante pensionado con mesada superior a 25 SMLMV | CY9: 13551508 RETENCION EN LA FUENTE SERVICIOS DE RESTAURANTE 3.5%0,035 | DE9: Manejo de Produccion | DG9: Lugar de nacimiento de la madre | DM9: Docena - Docena | DO9: Zonas y Terceros Excluidos | DU9: ='Cargos Nomina-Centros de trabaj'!B9 -> 0 | DW9: Zonas y Terceros Excluidos
A10: COMFACOR EPS S | C10: FONDO NACIONAL DEL AHORRO | E10: CAJA DE COMPENSACION FAMILIAR DE BARRANCABERMEJA | G10: LIBERTY SEGUROS DE VIDA | I10: Auxilio Vehiculo (No Salarial) | M10: Bonificación Permanente | Q10: Persona Natural o Juridica Ley 1429 | S10: PASAPORTE | U10: Agua De Dios | Y10: Fco. | AA10: PROPIEDAD HORIZONTAL | AE10: Servicio | AG10: 131095 OTRAS | AI10: Medicina Descuento | AU10: Socio; | AW10: Hora Extra Nocturna | AY10: 104 Elaboración de productos lácteos. | BA10: 410555 CRIA DE GANADO CABALLAR Y VACUNO. | BE10: 6145 TRANSPORTE, ALMACENAMIENTO Y COMUNICACIONES | BG10: BANCO DE CREDITO DE COLOMBIA | BM10: Servicio | BY10: Profesor de establecimiento particular | CC10: Residente en el exterior afiliado voluntario al Sistema General de Pensiones y/o afiliado facultativo al Sistema de Subsidio Familiar Decreto 682 de 2014 | CY10: 13551509 RETENCION EN LA FUENTE ARRENDAMIENTO BIENES INMUEBLES0,035 | DE10: Nómina y recursos humanos | DG10: Mejor amigo de la infancia | DM10: Frasco - Fco. | DU10: ='Cargos Nomina-Centros de trabaj'!B10 -> 0
A11: COMFAMILIAR HUILA EPS - CCF | E11: CAJA DE COMPENSACION FAMILIAR DE LA GUAJIRA | G11: MAPFRE COLOMBIA VIDA SEGUROS SA | I11: Auxilio Vivienda P (Salarial) | M11: Bonificación por retiro (No Salarial) | Q11: Persona Natural Responsable del IVA | S11: Permiso especial de permanencia | U11: Aguachica | Y11: g/m | AA11: SERVICIOS | AE11: Título Valor | AG11: 131505 VENTAS | AI11: Seguro Vida Autodescuento | AU11: Transportador; | AW11: Sueldo | AY11: 1040 Elaboración de productos lácteos. | BA11: 410560 PRODUCCION AVICOLA | BE11: 6150 ACTIVIDAD FINANCIERA | BG11: BANCO DE OCCIDENTE | BM11: Título Valor | BY11: Estudiantes aportes solo riesgos laborales | CC11: Conductores del servicio público de transporte terrestre automotor individual de pasajeros en vehículos taxi Decreto 1047 de 2014 | CY11: 13551510 RETENCION EN LA FUENTE TARJETAS CREDITO Y DEBITO 1.5%0,015 | DE11: Revisor Fiscal | DG11: Nombre de la primera Mascota | DM11: Gramos por m - g/m | DU11: ='Cargos Nomina-Centros de trabaj'!B11 -> 0
A12: COMFENALCO ANTIOQUIA | E12: CAJA DE COMPENSACION FAMILIAR DE NARIÑO | G12: POSITIVA COMPAÑÍA DE SEGUROS | I12: Bonificación Mera Liberalidad P (No Salarial) | M12: Bonificación semana Santa | Q12: Persona Natural Responsable del IVA Agente retenedor | S12: REGISTRO CIVIL | U12: Aguada | Y12: g/m² | AG12: 131510 PAGOS A NOMBRE DE CASA MATRIZ | AU12: Vendedor; | AY12: 105 Elaboración de productos de molinería, almidones y productos derivados del almidón. | BA12: 410565 CRIA DE OTROS ANIMALES | BE12: 6155 ACTIVIDADES INMOBILIARIAS, EMPRESARIALES Y DE ALQUILER | BG12: BANCO GNB SUDAMERIS | BY12: Dependiente Entidades o Universidades Publicas con régimen especial en salud | CC12: Conductores del servicio taxi no aporte a pensión Decreto 1047 | CY12: 13551511 AUTORRETENCION ESPECIAL A TITULO DE RENTA Y COMPLEMENTARIOS0 | DE12: Tecnico en sistemas | DG12: Nombre de su primer profesor | DM12: Gramos por m² - g/m² | DU12: ='Cargos Nomina-Centros de trabaj'!B12 -> 0
A13: COMFENALCO VALLE EPS | E13: CAJA DE COMPENSACION FAMILIAR DE SUCRE | G13: SEGUROS DE VIDA AURORA | I13: Bonificación Permanente | M13: Bonos electrónicos o en papel, recargas y vales NS | Q13: Proveedor Sociedades de Comercio Internacional | S13: Sin identificación del exterior o para uso definido por la DIAN | U13: Aguadas | Y13: gal | AG13: 131515 VALORES RECIBIDOS POR CASA MATRIZ | AU13: Proveedor;Cliente; | AY13: 1051 Elaboración de productos de molinería. | BA13: 410570 SERVICIOS AGRICOLAS Y GANADEROS | BE13: 6160 ENSEÑANZA | BG13: BANCO POPULAR | BY13: Cooperados o Precooperativas de trabajo asociado | CY13: 13551512 AUTORETENCIÓN EN LA FUENTE VENTA PRODUCTOS REGIMEN SIMPLE TRIBUTACIÓN0,025 | DG13: Ocupacion del abuelo | DM13: Galón - gal | DU13: ='Cargos Nomina-Centros de trabaj'!B13 -> 0
A14: COMPENSAR EPS | E14: CAJA DE COMPENSACION FAMILIAR DED CARTAGENA | G14: SEGUROS DE VIDA DEL ESTADO S.A. | I14: Bonificación por retiro (No Salarial) | M14: Bonos electrónicos o en papel, recargas y vales S | Q14: Régimen Simple de Tributación Persona Juridica | S14: TE | U14: Aguazul | Y14: Garrafa | AG14: 131520 PRESTAMOS | AU14: Proveedor;Cliente;Socio; | AY14: 1052 Elaboración de almidones y productos derivados del almidón. | BA14: 410575 ACTIVIDAD DE CAZA | BE14: 6165 SERVICIOS SOCIALES Y DE SALUD | BG14: BANCO SANTANDER | BY14: Trabajador dependiente de entidad beneficiaria del Sistema General de Participaciones - aportes patronales | CY14: 13551513 AUTORETENCIÓN EN LA FUENTE VENTA SERVICIOS REGIMEN SIMPLE TRIBUTACIÓN0,04 | DG14: Personaje Historico Favorito | DM14: Garrafa (5 gal) - Garrafa | DU14: ='Cargos Nomina-Centros de trabaj'!B14 -> 0
A15: CONDOR EPS | E15: CAJA DE COMPENSACION FAMILIAR DEL CESAR | I15: Bonificación semana Santa | M15: Bonos electrónicos, en papel, vales alimentación S | Q15: Régimen Simple de Tributación Persona Natural | S15: TI | U15: Agustín Codazzi | Y15: h | AG15: 132005 FILIALES | AU15: Empleado;Vendedor; | AY15: 106 Elaboración de productos de café. | BA15: 410580 ACTIVIDAD DE SILVICULTURA | BE15: 6170 OTRAS ACTIVIDADES DE SERVICIOS COMUNITARIOS, SOCIALES Y PERSONALES | BG15: BANCOLOMBIA | BY15: Trabajador de tiempo parcial Afiliado al Régimen Subsidiado | CY15: 13551514 AUTORETENCIÓN EN LA FUENTE VENTA ARRENDAMIENTOS REGIMEN SIMPLE0,035 | DG15: Primer numero de telefono | DM15: Hora - h | DU15: ='Cargos Nomina-Centros de trabaj'!B15 -> 0
A16: CONVIDA | E16: CAJA DE COMPENSACION FAMILIAR DEL ORIENTE | I16: Bonos electrónicos o en papel, recargas y vales NS | M16: Bonos1 electrónicos o en papel,vales alimentac. NS | Q16: Tercero del Exterior | U16: Aipe | Y16: kg | AG16: 132010 SUBSIDIARIAS | AU16: Cliente;Socio; | AY16: 1061 Trilla de café. | BA16: 410599 AJUSTES POR INFLACION | BE16: 6195 OTROS COSTOS | BG16: CITIBANK | BY16: Prepensionado de entidad en liquidación | DG16: Profesor favorito | DM16: Kilogramo - kg | DU16: ='Cargos Nomina-Centros de trabaj'!B16 -> 0
A17: COOMEVA EPS | E17: CAJASAI | I17: Bonos electrónicos o en papel, recargas y vales S | M17: Cesantia | U17: Albán | Y17: kg/m | AG17: 132015 SUCURSALES | AY17: 1062 Descafeinado, tostión y molienda del café. | BA17: 411005 ACTIVIDAD DE PESCA | BG17: HSBC COLOMBIA | BY17: Pre pensionado con aportevoluntario en salud | DG17: Segundo nombre de su padre | DM17: Kilgramos por metro - kg/m | DU17: ='Cargos Nomina-Centros de trabaj'!B17 -> 0
A18: CRUZ BLANCA EPS | E18: CAJASAN | I18: Bonos electrónicos, en papel, vales alimentación S | M18: Comisiones | U18: Albán | Y18: km | AG18: 132505 CUENTAS POR COBRAR A SOCIOS | AY18: 1063 Otros derivados del café. | BA18: 411010 EXPLOTACION DE CRIADEROS DE PECES | BY18: Independiente voluntario al sistema de Riesgos Laborales | DM18: kilómetro - km | DU18: ='Cargos Nomina-Centros de trabaj'!B18 -> 0
A19: EMPRESAS PUBLICAS DE MEDELLIN DEPARTAMENTO MEDICO | E19: CAMACOL | I19: Bonos Sodexo Mercado | M19: Compensaciones Extraordinarias P | U19: Albania | Y19: l | AG19: 132510 A ACCIONISTAS | AY19: 107 Elaboración de azúcar y panela. | BA19: 411095 ACTIVIDADES CONEXAS | BY19: Estudiantes de prácticas laborales en el sector público | DM19: Litro - l | DU19: ='Cargos Nomina-Centros de trabaj'!B19 -> 0
A20: EPS COMFABOY | E20: COFREM META | I20: Bonos1 electrónicos o en papel,vales alimentac. NS | M20: Compensaciones Ordinarias P | U20: Albania | Y20: LB | AG20: 133005 A PROVEEDORES | AY20: 1071 Elaboración y refinación de azúcar. | BA20: 411099 AJUSTES POR INFLACION | BY20: Pensionado | DM20: Libra - LB | DU20: ='Cargos Nomina-Centros de trabaj'!B20 -> 0
A21: FAMISANAR EPS CAFAM - COLSUBSIDIO | E21: COMBARRANQUILLA | I21: Comisiones | M21: Cuota de Sostenimiento | U21: Albania | Y21: m | AG21: 133010 A CONTRATISTAS | AY21: 1072 Elaboración de panela. | BA21: 4115 EXPLOTACION DE MINAS Y CANTERAS | DM21: Metros - m | DU21: ='Cargos Nomina-Centros de trabaj'!B21 -> 0
A22: FONDO DE PASIVO SOCIAL DE FERROCARRILES | E22: COMCAJA | I22: Compensaciones Extraordinarias P | M22: Dotación P | U22: Alcalá | Y22: m/kg | AG22: 133015 A TRABAJADORES | AY22: 108 Elaboración de otros productos alimenticios. | BA22: 411505 CARBON | DM22: Metros por Kilogramo - m/kg
A23: FONDO DE SOLIDARIDAD Y GARANTIA MINISTERIO DE SALUD | E23: COMFACA | I23: Compensaciones Ordinarias P | M23: Festivo Doble | U23: Aldana | Y23: m² | AG23: 133020 A AGENTES | AY23: 1081 Elaboración de productos de panadería. | BA23: 411510 PETROLEO CRUDO | DM23: Metros Cuadrado - m²
A24: GOLDEN GROUP EPS | E24: COMFACASANARE | I24: Cuota de Sostenimiento | M24: Festivo Sencillo | U24: Alejandría | Y24: m³ | AG24: 133025 A CONCESIONARIOS | AY24: 1082 Elaboración de cacao, chocolate y productos de confitería. | BA24: 411512 GAS NATURAL | DM24: Metros Cubicos - m³
A25: HUMANA VIVIR EPS | E25: COMFACAUCA | I25: Cuota Sindicato Causación | M25: Hora Extra Diurna | U25: Algarrobo | Y25: mes | AG25: 133030 DE ADJUDICACIONES | AY25: 1083 Elaboración de macarrones, fideos, alcuzcuz y productos farináceos similares. | BA25: 411514 SERVICIOS RELACIONADOS CON EXTRACCION DE PETROLEO Y GAS | DM25: Mes - mes
A26: INSTITUTO DE SEGUROS SOCIALES | E26: COMFACOR EPS S | I26: Cuota Sindicato Descuento P | M26: Hora Extra Dominical Diurna | U26: Algeciras | Y26: min | AG26: 133095 OTROS | AY26: 1084 Elaboración de comidas y platos preparados. | BA26: 411515 MINERALES DE HIERRO | DM26: Minutos - min
A27: NUEVA EPS | E27: COMFAMILIAR ATLANTICO | I27: Daño computadores P | M27: Hora Extra Dominical Nocturna | U27: Almaguer | Y27: ML | AG27: 133505 PARA IMPORTACIONES | AY27: 1089 Elaboración de otros productos alimenticios n.c.p. | BA27: 411520 MINERALES METALIFEROS NO FERROSOS | DM27: Mililitro - ML
A28: RED SALUD EPS | E28: COMFAMILIAR HUILA EPS - CCF | I28: Descuentos | M28: Hora Extra Festiva Nocturna | U28: Almeida | Y28: mm | AG28: 133510 PARA SERVICIOS | AY28: 109 Elaboración de alimentos preparados para animales. | BA28: 411525 PIEDRA, ARENA Y ARCILLA | DM28: Milímetro - mm
A29: SALUD COLOMBIA EPS | E29: COMFAMILIAR RISARALDA | I29: Dotación P | M29: Hora Extra Festiva Diurna | U29: Alpujarra | Y29: Oz | AG29: 133515 PARA CONTRATOS | AY29: 1090 Elaboración de alimentos preparados para animales. | BA29: 411527 PIEDRAS PRECIOSAS | DM29: Onzas - Oz
A30: SALUD COLPATRIA EPS | E30: COMFANDI | I30: Educación Causación | M30: Hora Extra Nocturna | U30: Altamira | Y30: Pq | AG30: 133520 PARA RESPONSABILIDADES | AY30: 11 Cultivos agrícolas transitorios. | BA30: 411528 ORO | DM30: Paquete - Pq
A31: SALUD TOTAL EPS | E31: COMFATOLIMA | I31: Educación Descuento | M31: Hora Recargo Dominical | U31: Alto Baudo | Y31: seg | AG31: 133525 PARA JUICIOS EJECUTIVOS | AY31: 110 Elaboración de bebidas. | BA31: 411530 OTRAS MINAS Y CANTERAS | DM31: Segundo - seg
A32: SALUD VIDA EPS | E32: COMFENALCO ANTIOQUIA | I32: Embargo Judicial | M32: Hora Recargo Festivo | U32: Altos Del Rosario | Y32: sem | AG32: 133530 PARA ADQUISICION DE ACCIONES, CUOTAS O DERECHOS SOCIALES | AY32: 1101 Destilación, rectificación y mezcla de bebidas alcohólicas. | BA32: 411532 PRESTACION DE SERVICIOS SECTOR MINERO | DM32: Semana - sem
A33: SALUDCOOP EPS | E33: COMFENALCO CARTAGENA | I33: Festivo Doble | M33: Hora Recargo Noctuno | U33: Alvarado | Y33: Tn | AG33: 133535 EN GARANTIA | AY33: 1102 Elaboración de bebidas fermentadas no destiladas. | BA33: 411595 ACTIVIDADES CONEXAS | DM33: Tonelada - Tn
... A35: SELVASALUD EPS | E35: COMFENALCO SANTANDER | I35: Fondo de Solidaridad | M35: Incapacidad EPS | U35: Amalfi | Y35: Und. | AG35: 134005 DE BIENES RAICES | AY35: 1104 Elaboración de bebidas no alcohólicas, producción de aguas minerales y de otras aguas embotelladas. | BA35: 4120 INDUSTRIAS MANUFACTURERAS | DM35: Unidad - Und.
A36: SERVICIO OCCIDENTAL DE SALUD | E36: COMFENALCO TOLIMA | I36: Hora Recargo Noctuno | M36: Incapacidades | U36: Ambalema | AG36: 134010 DE MAQUINARIA Y EQUIPO | AY36: 111 Cultivo de cereales (excepto arroz), legumbres y semillas oleaginosas. | BA36: 412001 PRODUCCION Y PROCESAMIENTO DE CARNES Y PRODUCTOS CARNICOS
A37: SOLSALUD EPS | E37: COMFENALCO VALLE | I37: Huelgas Legales P | M37: Indemnización | U37: Anapoima | AG37: 134015 DE FLOTA Y EQUIPO DE TRANSPORTE | AY37: 112 Cultivo de arroz. | BA37: 412002 PRODUCTOS DE PESCADO
A38: SURA EPS | E38: COMPENSAR EPS | I38: Incapacidad ARL | M38: Intereses sobre Cesantias | U38: Ancuyá | AG38: 134020 DE FLOTA Y EQUIPO AEREO | AY38: 113 Cultivo de hortalizas, raíces y tubérculos. | BA38: 412003 PRODUCTOS DE FRUTAS, LEGUMBRES Y HORTALIZAS
A39: SUSALUD EPS | E39: EPS COMFABOY | I39: Incapacidad EPS | M39: Licencia de Luto | U39: Andalucía | AG39: 134025 DE FLOTA Y EQUIPO FERREO | AY39: 114 Cultivo de tabaco. | BA39: 412004 ELABORACION DE ACEITES Y GRASAS
A40: UNIVERSIDAD DEL ATLANTICO | I40: Incapacidades | M40: Licencia de Maternidad | U40: Andes | AG40: 134030 DE FLOTA Y EQUIPO FLUVIAL Y/O MARITIMO | AY40: 115 Cultivo de plantas textiles. | BA40: 412005 ELABORACION DE PRODUCTOS LACTEOS
A41: UNIVERSIDAD DEL VALLE | I41: Indemnización | M41: Licencia Remunerada | U41: Angelópolis | AG41: 134035 DE SEMOVIENTES | AY41: 119 Otros cultivos transitorios n.c.p. | BA41: 412006 ELABORACION DE PRODUCTOS DE MOLINERIA
...

Sheet Cargos Nomina-Centros de trabaj
A1: Id Cargo | B1: Cargo | D1: CENTROS DE TRABAJO
A2: 1 | B2: Auxiliar Contable | C2: Ejemplo
A3: 2 | B3: Mensajero | C3: Ejemplo | D3: Ejemplo: Cada uno de las sucursales de Almacenes Éxito es un Centro de Trabajo ya que los empleados de esta empresa asisten allí a laborar, es decir éxito calle 80, Américas, Calle 53, Éxito Kenedy, Éxito 20 de Julio etc. son Centros de trabajo para esta empresa.
A4: 3 | B4: Servicios Generales | C4: Ejemplo
A5: 4 | B5: Gerente | C5: Ejemplo | D5: Aclaración: Si todos los empleados de su empresa trabajan virtualmente el centro de trabajo será la dirección que se tiene registrada en la cámara de comercio
A6: 5 | B6: Vendedor | C6: Ejemplo
F8: Código | G8: Centro de Trabajo | H8: Dirección | I8: Ciudad
F9: 1 | G9: Zona Sur Bogota | H9: Cra. 59a #79 - 30 | I9: Bogota D.C. | J9: Ejemplo
F10: 2 | G10: Sede Principal | H10: Av. de las Américas # 68 A - 94 | I10: Bogota D.C. | J10: Ejemplo

Sheet Información Empleados
A1: Tipo Identificación | B1: Identificación | C1: Identificación Ciudad | D1: Primer Nombre | E1: Segundo Nombre | F1: Primer Apellido | G1: Segundo Apellido | H1: Tipo Contrato | I1: Fecha Ingreso | J1: Area | K1: Clase | L1: Empresa | M1: Cargo | N1: Sueldo | O1: Periodo Pago | P1: Centro Costos | Q1: Clasificación Dian | R1: Cesantias | S1: IntCesantias | T1: Prima | U1: Vacaciones | V1: Ret. Fte | W1: Fecha Nacimiento | X1: Ciudad | Y1: Tipo Dirección | Z1: Direccion | AA1: Teléfono | AB1: E_Mail | AC1: Número hijos | AD1: Estado Civil | AE1: Declarante | AF1: Dotación | AG1: Tipo Cuenta | AH1: Número Cuenta | AI1: Banco Cuenta | AJ1: Tipo Sena | AK1: Fecha Fin Periodo Prueba | AL1: Fecha Fin Contrato | AM1: ARL | AN1: Fecha Afil. ARL | AO1: Tarifa ARL | AP1: EPS | AQ1: Fecha Afil. EPS | AR1: Pensión | AS1: Fecha Afil. AFP | AT1: Fondo Cesantias | AU1: Fecha Afil. Fondo Cesantías | AV1: Caja de Compensacion | AW1: Fecha Afil. Caja | AX1: Código Centro Costos | AY1: Libreta Militar No. | AZ1: Sexo | BA1: Centro De Trabajo | BB1: Tipo Cotizante | BC1: Sub tipo Cotizante
A2: CC | B2: 1023563089 | C2: Abejorral | D2: MARIA | E2: ROSA | F2: PEREZ | G2: LONDOÑO | H2: Fijo | I2: 43466 | J2: Administrativa | K2: Aprendiz SENA | L2: Empresa XYZ SAS | M2: Auxiliar Contable | N2: 1200000 | O2: Mensual | P2: Administracion | Q2: Normal | R2: -1 | S2: 0 | T2: 0 | U2: 0 | V2: 0 | W2: 34700 | X2: Abejorral | Y2: Empresa/Oficina | Z2: CL 50 04 01 | AA2: 2567895 | AB2: empleado1@hotmail.com | AD2: Soltero | AE2: 0 | AF2: -1 | AG2: Nequi | AH2: 124125452 | AI2: ABN AMRO BANK | AJ2: Aprendices del SENA en etapa lectiva | AL2: 43830 | AM2: ARL SEGUROS DE VIDA COLPATRIA SA | AN2: 43466 | AO2: 6.96 | AP2: CONVIDA | AQ2: 43466 | AR2: COLPENSIONES | AS2: 43466 | AT2: COLPENSIONES | AU2: 43466 | AV2: CAJA COLOMBIANA DE SUBSIDIO FAMILIAR COLSUBSIDIO | AW2: 43466 | AZ2: Femenino | BA2: Zona Sur Bogota | BB2: Aprendices del SENA en etapa lectiva | BC2: Ninguno
A3: CC | B3: 1010123655 | C3: San Andrés | D3: ELSA | F3: RUEDA | G3: LONDOÑO | H3: Indefinido | I3: 43466 | J3: Administrativa | K3: Normal | L3: Empresa XYZ SAS | M3: Mensajero | N3: 2100000 | O3: Quincenal | P3: Ventas | Q3: Normal | R3: -1 | S3: -1 | T3: 0 | U3: 0 | V3: 0 | W3: 32994 | X3: Abejorral | Y3: Casa | Z3: CR 51 45 02 | AA3: 2541236 | AB3: empleado2@hotmail.com | AC3: 3 | AD3: Casado | AE3: 0 | AF3: -1 | AG3: Corriente | AH3: 45787878 | AI3: BANCO AV VILLAS | AM3: COMPAÑÍA DE SEGUROS BOLIVAR SA | AN3: 43466 | AO3: 4.35 | AP3: FAMISANAR EPS CAFAM - COLSUBSIDIO | AQ3: 43466 | AR3: PROTECCIÓN S.A. AFPC | AS3: 43466 | AT3: PROTECCIÓN S.A. AFPC | AU3: 43466 | AV3: CAJA COLOMBIANA DE SUBSIDIO FAMILIAR COLSUBSIDIO | AW3: 43466 | AZ3: Femenino | BA3: Zona Sur Bogota | BB3: Pensionado | BC3: Dependiente pensionado por vejez activo
A4: CC | B4: 52563896 | C4: Bogota D.C. | D4: ROCIO | F4: RICO | H4: Definido menos de un año | I4: 43466 | J4: Administrativa | K4: Salario Inferior al Minimo | L4: Empresa XYZ SAS | M4: Servicios Generales | N4: 950000 | O4: Mensual | P4: Produccion | Q4: Normal | R4: -1 | S4: -1 | T4: -1 | U4: 0 | V4: 0 | W4: 33817 | X4: Abejorral | Y4: Bodega | Z4: CL 5 45 02 | AA4: 2547485 | AB4: empleado3@hotmail.com | AC4: 2 | AD4: Separado | AE4: 0 | AF4: -1 | AG4: DaviPlata | AH4: 3120000000 | AI4: BANCO DAVIVIENDA | AL4: 43830 | AM4: ARL SURA | AN4: 43466 | AO4: 2.436 | AP4: FAMISANAR EPS CAFAM - COLSUBSIDIO | AQ4: 43466 | AR4: COLPENSIONES | AS4: 43466 | AT4: PROTECCIÓN S.A. AFPC | AU4: 43466 | AV4: CAJA COLOMBIANA DE SUBSIDIO FAMILIAR COLSUBSIDIO | AW4: 43466 | AZ4: Femenino | BA4: Zona Sur Bogota | BB4: Dependiente | BC4: Ninguno
A5: CC | B5: 80523563 | C5: Rosas | D5: LUIS | E5: ALFONSO | F5: MUÑOZ | G5: PEREZ | H5: Labor Contratada | I5: 43466 | J5: Administrativa | K5: Aprendiz SENA | L5: Empresa XYZ SAS | M5: Gerente | N5: 900000 | O5: Semanal | P5: Administracion | Q5: Normal | R5: -1 | S5: -1 | T5: -1 | U5: -1 | V5: 0 | W5: 33970 | X5: Abejorral | Y5: Sucursal | Z5: TV 48 45 03 | AA5: 2541236 | AB5: empleado1@hotmail.com | AC5: 4 | AD5: Union Libre | AE5: -1 | AF5: 0 | AG5: Ahorros | AH5: 15487878 | AI5: BANCO DE BOGOTA | AJ5: Aprendices del SENA en etapa productiva | AL5: 43830 | AM5: ARL SURA | AN5: 43466 | AO5: 1.044 | AP5: FAMISANAR EPS CAFAM - COLSUBSIDIO | AQ5: 43466 | AR5: COLPENSIONES | AS5: 43466 | AT5: PROTECCIÓN S.A. AFPC | AU5: 43466 | AV5: CAJA COLOMBIANA DE SUBSIDIO FAMILIAR COLSUBSIDIO | AW5: 43466 | AZ5: Masculino | BA5: Sede Principal | BB5: Aprendices del SENA en etapa productiva | BC5: Ninguno
A6: CC | B6: 1020202256 | C6: Tenerife | D6: FABIAN | F6: MARTINEZ | G6: ROJAS | H6: Fijo | I6: 43466 | J6: Administrativa | K6: Salario Integral | L6: Empresa XYZ SAS | M6: Vendedor | N6: 15080000 | O6: Mensual | P6: Ventas | Q6: Normal | R6: 0 | S6: 0 | T6: 0 | U6: -1 | V6: -1 | W6: 34820 | X6: Abejorral | Y6: Casa | Z6: CL 52 04 03 | AA6: 2896523 | AB6: empleado2@hotmail.com | AC6: 1 | AD6: Soltero | AE6: 0 | AF6: -1 | AG6: Ahorros | AH6: 2787545785 | AI6: ABN AMRO BANK | AL6: 43830 | AM6: ARL SURA | AN6: 43466 | AO6: 0.522 | AP6: FAMISANAR EPS CAFAM - COLSUBSIDIO | AQ6: 43466 | AR6: COLPENSIONES | AS6: 43466 | AT6: PROTECCIÓN S.A. AFPC | AU6: 43466 | AV6: CAJA COLOMBIANA DE SUBSIDIO FAMILIAR COLSUBSIDIO | AW6: 43466 | AZ6: Masculino | BA6: Sede Principal | BB6: Dependiente | BC6: Ninguno
